Workbook

Sheet Portada
B4: Elaboración Propuesta Fichas Técnicas Proyecto CheerClick Systems
C8: Integrantes: | E8: Dilan Rodriguez, Antony Cardenas, Brayan Corpa, Felipe Lasprilla
C10: Roles del club deportivo: Administrador, Entrenador, Cliente.
F13: ADSO - 3354284

Sheet Portatil admid
D2: CUADRO DE COTIZACIONES
A5: Cuadro Comparativo de Cotizaciones
A7: Presupuestos (a) | B7: Empresa (Nombre fiscal de la empresa) | C7: Nº de CUIT, Dirección, Teléfono (Datos de la empresa) | D7: Descripción del bien/ servicio (b) Características de los bienes/ servicios | E7: Importe Unitario (moneda nacional) | F7: Importe Total IVA incluido (moneda nacional) | G7: Importe Total (moneda extranjera) | H7: Tipo de cambio | I7: Forma de Pago (Contado o Cheque) | J7: Garantía | K7: Observaciones (se debe incluir toda aquella característica que no ha sido posible incluir anteriormente)
A8: Nº 1 | B8: Ktronix | C8: https://www.ktronix.com/computador-portatil-lenovo-ideapad-slim-3-153-pulgadas/p/198155958762 | D8: Computador Portátil LENOVO Ideapad Slim 3 - 15.3" Pulgadas 15HP10 - AMD Ryzen 5 - RAM 24GB - Disco SSD 512GB - Azul | E8: 2499070 | F8: 2749000 | G8: 474,18 | H8: 3685.53 | I8: Contado | J8: 1 año | K8: El Lenovo V14 AMN tiene Ryzen 5 7520U, 16 GB RAM, SSD 512 GB y pantalla 14″ Full HD, con gráficos Radeon 610M, WiFi ac y FreeDOS.
A9: Nº2 | B9: Exito | C9: https://www.exito.com/portatil-lenovo-v14-g4-amn-amd-ryzen-5-7520u-16gb-ssd512gb-156-win-11-de-prueba-103253633-mp/p?idsku=103253633&srsltid=AfmBOoqdyqQH0j3UkD2IZrM8MsVXaowHdOoFs179VDVw_O-FFEt5L5RPZyE | D9: Portátil Lenovo V14 G4 Ryzen 5 7520U 16Gb Ram 512Gb Ssd 14 Pulgadas Fhd | E9: 1415462.2 | F9: 1684400 | G9: 456,67 | H9: 3685.53 | I9: Contado | J9: 1 año | K9: El Lenovo V14 de 4.ª generación con AMD Ryzen ofrece buen rendimiento, Wi-Fi 6, Bluetooth 5.0, varios puertos y resistencia militar 810H, ideal para trabajo o estudio.
A10: Nº 3 | B10: Mercado libre | C10: https://www.mercadolibre.com.co/portatil-lenovo-v14-g4-amn-amd-ryzen-5-7520u-16gb-512gb-fhd-14-color-gris/p/MCO45053079?pdp_filters=item_id%3AMCO2947822406&from=gshop&matt_tool=87585337&matt_word=&matt_source=google&matt_campaign_id=22126928786&matt_ad_group_id=173140661443&matt_match_type=&matt_network=g&matt_device=c&matt_creative=729836849962&matt_keyword=&matt_ad_position=&matt_ad_type=pla&matt_merchant_id=735127761&matt_product_id=MCO45053079-product&matt_product_partition_id=2389933078058&matt_target_id=pla-2389933078058&cq_src=google_ads&cq_cmp=22126928786&cq_net=g&cq_plt=gp&cq_med=pla&gad_source=4&gad_campaignid=22126928786&gclid=Cj0KCQjwsdnNBhC4ARIsAA_3hehZmNmorHRXA7_8HlblU0iW2-kiIXruU_z4KOS5hmAN95fsypdjtcEaAm1KEALw_wcB | D10: Portatil Lenovo V14 G4 AMN AMD Ryzen 5 7520U 16gb 512gb Fhd 14 Color Gris | E10: 1406092.4 | F10: 1673250 | G10: 453,64 | H10: 3685.53 | I10: Contado | J10: 1 año | K10: Portatil Lenovo V14 G4 AMN AMD Ryzen 5 7520U 16gb 512gb Fhd 14 Color Gris
A13: (a) Se deben presentar tres (3) presupuestos cuando: El valor del gasto supere el monto de pesos un mil ($ 1.000,00). Se pueden presentar al menos tres (3) solicitudes de cotización (del bien o servicio a contratar) cursadas a tres o más empresas oferentes. La selección del proveedor se hará con el criterio del más bajo precio. En caso de no contar con tres (3) presupuestos, o no poder seleccionar al proveedor que ofrece menor precio, presentar este cuadro una nota de justificación siguiendo las pautas del ítem (XX)
A15: (b) Ejemplos: En el caso de viajes, indicar Origen/Destino (si corresponde también escalas) Si se tratara de servicios tipo catering, indicar las cantidades de asistentes, así como los días en que se demanda la prestación del servicio. Si fuera papelería indicar, cantidades de afiches, trípticos, etc.

Sheet Ram portatil Admin
D2: CUADRO DE COTIZACIONES
A5: Cuadro Comparativo de Cotizaciones
A7: Presupuestos (a) | B7: Empresa (Nombre fiscal de la empresa) | C7: Nº de CUIT, Dirección, Teléfono (Datos de la empresa) | D7: Descripción del bien/ servicio (b) Características de los bienes/ servicios | E7: Importe Unitario (moneda nacional) | F7: Importe Total IVA incluido (moneda nacional) | G7: Importe Total (moneda extranjera) | H7: Tipo de cambio | I7: Forma de Pago (Contado o Cheque) | J7: Garantía | K7: Observaciones (se debe incluir toda aquella característica que no ha sido posible incluir anteriormente)
A8: Nº 1 | B8: Exito | C8: https://www.exito.com/memoria-ram-16gb-ddr4-3200mhz-attech-para-portatil-104852224-mp/p?idsku=104852224&srsltid=AfmBOooaU4HzfFuGmZoUy9X8MdqiUeIpSI_pPfZC4B6p64bIrDdUj0puV2I | D8: 16 RAM | E8: 503361.34 | F8: 599000 | G8: 162,18 | H8: 3685.53 | I8: Contado | J8: 1 año | K8: Ddr4 3200Mhz Attech Para Portatil
A9: Nº2 | B9: Mercado libre | C9: https://www.mercadolibre.com.co/memoria-ram-portatil-attech-ddr4-16gb-3200mhz/p/MCO52290549?matt_tool=19390127&utm_source=google_shopping&utm_medium=organic&pdp_filters=item_id%3AMCO2945863306&from=gshop | D9: 16 RAM | E9: 526890.76 | F9: 627000 | G9: 169,77 | H9: 3685.53 | I9: Contado | J9: 36 meses | K9: Optimizá el rendimiento de tu máquina con la tecnología DDR4.
A10: Nº 3 | B10: Falabella | C10: https://www.falabella.com.co/falabella-co/product/126378737/Memoria-ram-crucial-ddr4-16gb-3200mhz-portatil/126378738 | D10: 16 RAM | E10: 453697.48 | F10: 539900 | G10: 146,18 | H10: 3685.53 | I10: Contado | J10: 6 meses | K10: ddr4 16gb-3200mhz portatil
I11: Contado
A13: (a) Se deben presentar tres (3) presupuestos cuando: El valor del gasto supere el monto de pesos un mil ($ 1.000,00). Se pueden presentar al menos tres (3) solicitudes de cotización (del bien o servicio a contratar) cursadas a tres o más empresas oferentes. La selección del proveedor se hará con el criterio del más bajo precio. En caso de no contar con tres (3) presupuestos, o no poder seleccionar al proveedor que ofrece menor precio, presentar este cuadro una nota de justificación siguiendo las pautas del ítem (XX)
A15: (b) Ejemplos: En el caso de viajes, indicar Origen/Destino (si corresponde también escalas) Si se tratara de servicios tipo catering, indicar las cantidades de asistentes, así como los días en que se demanda la prestación del servicio. Si fuera papelería indicar, cantidades de afiches, trípticos, etc.

Sheet Disco duro externo Portatil Adm
D2: CUADRO DE COTIZACIONES
A5: Cuadro Comparativo de Cotizaciones
A7: Presupuestos (a) | B7: Empresa (Nombre fiscal de la empresa) | C7: Nº de CUIT, Dirección, Teléfono (Datos de la empresa) | D7: Descripción del bien/ servicio (b) Características de los bienes/ servicios | E7: Importe Unitario (moneda nacional) | F7: Importe Total IVA incluido (moneda nacional) | G7: Importe Total (moneda extranjera) | H7: Tipo de cambio | I7: Forma de Pago (Contado o Cheque) | J7: Garantía | K7: Observaciones (se debe incluir toda aquella característica que no ha sido posible incluir anteriormente)
A8: Nº 1 | B8: Mercado libre | C8: https://articulo.mercadolibre.com.co/MCO-2236719560-disco-duro-externo-de-1-tb-de-estilo-nuevo-_JM?matt_tool=19390127&utm_source=google_shopping&utm_medium=organic | D8: Disco duro Extendo 1 TB | E8: 41332.77 | F8: 49186 | G8: 13,32 | H8: 3685.53 | I8: Contado | J8: 60 días | K8: SSD portátil USB 3.1 con alta velocidad de transferencia, gran capacidad, conector OTG, diseño delgado y resistente de aluminio, y amplia compatibilidad con varios dispositivos.
A9: Nº2 | B9: Ktronix | C9: https://www.ktronix.com/disco-estado-solido-externo-ssd-kingston-xs1000-1tb-rojo/p/740617343748?utm_source=google&utm_medium=organic&utm_campaign=Shopping-organico&srsltid=AfmBOopSoaXg4kZta4TC0pM8kGWRhkvq21vh-XjaQANXGX_sZ_mSEwwnn0g | D9: Disco duro Extendo 1 TB | E9: 419327.73 | F9: 499000 | G9: 135,11 | H9: 3685.53 | I9: Contado | J9: 6 meses | K9: La SSD XS1000 de Kingston es compacta, ligera y rápida, ideal para guardar y transferir archivos fácilmente en cualquier lugar.
A10: Nº 3 | B10: Alkosto | C10: https://www.alkosto.com/disco-duro-toshiba-ready-1-tb/p/723844000851?utm_source=google&utm_medium=organic&utm_campaign=Shopping-Organico&srsltid=AfmBOoq20RRhpBms0yg02Lc1nei79ck9okHFJF9yeDTM7CqF4wGeGbYceyo | D10: Disco duro Extendo 1 TB | E10: 294033.61 | F10: 349000 | G10: 94,74 | H10: 3685.53 | I10: Contado | J10: 6 meses | K10: El disco duro portátil Canvio Ready de Toshiba ofrece 1TB de almacenamiento, funcionamiento plug and play y un diseño compacto y elegante, permitiendo guardar archivos fácilmente con solo arrastrar y soltar.
D11: Disco duro Extendo 1 TB | I11: Contado
A13: (a) Se deben presentar tres (3) presupuestos cuando: El valor del gasto supere el monto de pesos un mil ($ 1.000,00). Se pueden presentar al menos tres (3) solicitudes de cotización (del bien o servicio a contratar) cursadas a tres o más empresas oferentes. La selección del proveedor se hará con el criterio del más bajo precio. En caso de no contar con tres (3) presupuestos, o no poder seleccionar al proveedor que ofrece menor precio, presentar este cuadro una nota de justificación siguiendo las pautas del ítem (XX)
A15: (b) Ejemplos: En el caso de viajes, indicar Origen/Destino (si corresponde también escalas) Si se tratara de servicios tipo catering, indicar las cantidades de asistentes, así como los días en que se demanda la prestación del servicio. Si fuera papelería indicar, cantidades de afiches, trípticos, etc.

Sheet Almacenamiento Portatil Admin
D2: CUADRO DE COTIZACIONES
A5: Cuadro Comparativo de Cotizaciones
A7: Presupuestos (a) | B7: Empresa (Nombre fiscal de la empresa) | C7: Nº de CUIT, Dirección, Teléfono (Datos de la empresa) | D7: Descripción del bien/ servicio (b) Características de los bienes/ servicios | E7: Importe Unitario (moneda nacional) | F7: Importe Total IVA incluido (moneda nacional) | G7: Importe Total (moneda extranjera) | H7: Tipo de cambio | I7: Forma de Pago (Contado o Cheque) | J7: Garantía | K7: Observaciones (se debe incluir toda aquella característica que no ha sido posible incluir anteriormente)
A8: Nº 1 | B8: Unilago | C8: https://unilago.com/producto/53338-Disco-Est?srsltid=AfmBOoruL-lQfsUbrTJoBmfuCSMPbY4XcXWeFYUkaxdoZs6XwZYXag5VzcM | D8: 512 GB | E8: 325210.08 | F8: 387000 | G8: 104,78 | H8: 3685.53 | I8: Contado | J8: 36 meses | K8: Capacidad: 512 Gb\nVel. de Lectura: 1600MB/s\nVel. de Escritura: 1600MB/s\nFactor de Forma: M2 PCIE NVME\nGarantia: 36 meses
A9: Nº2 | B9: Mercado libre | C9: https://www.mercadolibre.com.co/disco-solido-ssd-interno-kingspec-ne512-512gb-m2-mvme-2280/up/MCOU2477622600 | D9: 512 GB | E9: 284873.95 | F9: 339000 | G9: 91,79 | H9: 3685.53 | I9: Contado | J9: 6 meses | K9: M.2 2280
A10: Nº 3 | B10: Exito | C10: https://www.exito.com/disco-duro-estado-solido-ssd-hiksemi-m2-pcie-nvme-512gb-104226281-mp/p?idsku=104226281&srsltid=AfmBOorUzAd3JS7H-EdGjUP3yMwNexywbYTmrkV28JZHi6ZmprT0P7ElqJc | D10: 512 GB | E10: 294033.61 | F10: 349900 | G10: 94,74 | H10: 3685.53 | I10: Contado | J10: 1 año | K10: Hiksemi M2 Pcie Nvme 512Gb
I11: Contado
A13: (a) Se deben presentar tres (3) presupuestos cuando: El valor del gasto supere el monto de pesos un mil ($ 1.000,00). Se pueden presentar al menos tres (3) solicitudes de cotización (del bien o servicio a contratar) cursadas a tres o más empresas oferentes. La selección del proveedor se hará con el criterio del más bajo precio. En caso de no contar con tres (3) presupuestos, o no poder seleccionar al proveedor que ofrece menor precio, presentar este cuadro una nota de justificación siguiendo las pautas del ítem (XX)
A15: (b) Ejemplos: En el caso de viajes, indicar Origen/Destino (si corresponde también escalas) Si se tratara de servicios tipo catering, indicar las cantidades de asistentes, así como los días en que se demanda la prestación del servicio. Si fuera papelería indicar, cantidades de afiches, trípticos, etc.

Sheet Mouse Admin
D2: CUADRO DE COTIZACIONES
A5: Cuadro Comparativo de Cotizaciones
A7: Presupuestos (a) | B7: Empresa (Nombre fiscal de la empresa) | C7: Nº de CUIT, Dirección, Teléfono (Datos de la empresa) | D7: Descripción del bien/ servicio (b) Características de los bienes/ servicios | E7: Importe Unitario (moneda nacional) | F7: Importe Total IVA incluido (moneda nacional) | G7: Importe Total (moneda extranjera) | H7: Tipo de cambio | I7: Forma de Pago (Contado o Cheque) | J7: Observaciones (se debe incluir toda aquella característica que no ha sido posible incluir anteriormente)
A8: Nº 1 | B8: Falabella | C8: https://www.falabella.com.co/falabella-co/product/127667703/Mouse-Logitech-M650-INALAMBRICO-GRIS/127667704 | D8: Mouse Logitech M650 | E8: 159579.83 | F8: 189900 | G8: 51,42 | H8: 3685.53 | I8: Contado | J8: El Logitech Signature M650 es un mouse inalámbrico con sensor óptico de hasta 4000 DPI, 5 botones, conexión USB o Bluetooth, batería de hasta 24 meses y diseño compacto con materiales reciclados.
A9: Nº2 | B9: Alkosto | C9: https://www.alkosto.com/mouse-logitech-inalambrico-optico-mediano-m650-gris/p/097855167637?utm_source=google&utm_medium=organic&utm_campaign=Shopping-Organico&srsltid=AfmBOoq_LcPgn-8EbwOkN8l4T0e4ZFuGI-3mamtXRjHucysBso3X2YDiGRQ | D9: Mouse Logitech M650 | E9: 151176.47 | F9: 179900 | G9: 48,71 | H9: 3685.53 | I9: Contado | J9: El Logitech Signature M650 ofrece comodidad y productividad, con rueda SmartWheel, clics silenciosos, botones personalizables y diseño ergonómico inalámbrico.
A10: Nº 3 | B10: Exito | C10: https://www.exito.com/mouse-inalambrico-logitech-m650-l-dual-usb-bluetooth-102123137-mp/p?idsku=102123137&srsltid=AfmBOortGD6votW2UoNZw-19jenH_pPPgxuCBUCokFRX8FrQzlMM34ac2gk | D10: Mouse Logitech M650 | E10: 155378.15 | F10: 184900 | G10: 50,06 | H10: 3685.53 | I10: Contado | J10: El Logitech Signature M650 L es un mouse inalámbrico ergonómico con rueda SmartWheel, clics silenciosos y conexión por Bluetooth o USB.
A13: (a) Se deben presentar tres (3) presupuestos cuando: El valor del gasto supere el monto de pesos un mil ($ 1.000,00). Se pueden presentar al menos tres (3) solicitudes de cotización (del bien o servicio a contratar) cursadas a tres o más empresas oferentes. La selección del proveedor se hará con el criterio del más bajo precio. En caso de no contar con tres (3) presupuestos, o no poder seleccionar al proveedor que ofrece menor precio, presentar este cuadro una nota de justificación siguiendo las pautas del ítem (XX)
A15: (b) Ejemplos: En el caso de viajes, indicar Origen/Destino (si corresponde también escalas) Si se tratara de servicios tipo catering, indicar las cantidades de asistentes, así como los días en que se demanda la prestación del servicio. Si fuera papelería indicar, cantidades de afiches, trípticos, etc.

Sheet Portatil nosotros
D2: CUADRO DE COTIZACIONES
A5: Cuadro Comparativo de Cotizaciones
A7: Presupuestos (a) | B7: Empresa (Nombre fiscal de la empresa) | C7: Nº de CUIT, Dirección, Teléfono (Datos de la empresa) | D7: Descripción del bien/ servicio (b) Características de los bienes/ servicios | E7: Importe Unitario (moneda nacional) | F7: Importe Total IVA incluido (moneda nacional) | G7: Importe Total (moneda extranjera) | H7: Tipo de cambio | I7: Forma de Pago (Contado o Cheque) | J7: Garantía | K7: Observaciones (se debe incluir toda aquella característica que no ha sido posible incluir anteriormente)
A8: Nº 1 | B8: Falabella | C8: https://www.falabella.com.co/falabella-co/product/147154185/portatil-asus-vivobook-amd-ryzen-7-5825u-ram-16gb-ssd-512gb-15-6-fhd/147154186?kid=shopp261fa&gclsrc=aw.ds&gad_source=1&gad_campaignid=21861273110&gclid=Cj0KCQjwsdnNBhC4ARIsAA_3hegpvyHLViWlBAhhXoGs4UDKBZR3Fx8dM9DdOwbuarbg8LYhg-yAfsEaApyJEALw_wcB | D8: Portátil ASUS VivoBook 15 Ryzen 7 5825U 16GB RAM 512GB SSD 15.6” FHD | E8: 1680663.9 | F8: 1999990 | G8: 542,23 | H8: 3685.53 | I8: Contado | J8: 1 año | K8: El ASUS Vivobook M1502YA ofrece Ryzen 7, 16 GB de RAM, SSD de 512 GB y pantalla 15.6″ Full HD.
A9: Nº2 | B9: Mercado libre | C9: https://www.mercadolibre.com.co/lenovo-v15-g4-156---core-i5-13a-generacion-16gb-ssd-1tb/up/MCOU3037567568?pdp_filters=item_id:MCO1547114667#polycard_client=recommendations_pdp-pads-up&reco_backend=recomm_platform_base_pads_ron_MERGE&reco_model=search_recos_backend_merge&reco_client=pdp-pads-up&reco_item_pos=4&reco_backend_type=low_level&reco_id=bd0b65ed-b2b2-4eaf-80dd-e0760deb96c8&wid=MCO1547114667&sid=recos&is_advertising=true&ad_domain=PDPDESKTOP_UP&ad_position=5&ad_click_id=ZDkxYzJkMDEtNTllYS00MjllLTlkNzctNTEwYWExNWJkNmVm | D9: Lenovo V15 G4 15.6 Core I5 13a Generación 16gb Ssd 1tb | E9: 2800000 | F9: 2979900 | G9: 536,78 | H9: 3685.53 | I9: Contado | K9: Ryzen 7 5825U, 16 GB RAM, SSD 512 GB, Windows 11 Home, pantalla Full HD (1920×1080), Bluetooth, teclado numérico y audio SonicMaster.
A10: Nº 3 | B10: Asus Colombia | C10: https://co.store.asus.com/90nb0x22-m017c0-portatil-portatil-asus-vivobook-15-m1502ya-r7-16gb-512gb-ssd-amd-radeon-15-m1502ya-nj180w.html?gad_source=4&gad_campaignid=17419861357&gclid=Cj0KCQjwsdnNBhC4ARIsAA_3hehifBu4LJkQTXtdsiGdK3S2Yzc9_kKTreCKiKNSasjNwQ2jO-E1ql8aAgZ8EALw_wcB | D10: Portátil ASUS Vivobook 15 (M1502YA-NJ180W) | E10: 1890672.3 | F10: 2249900 | G10: 609,98 | H10: 3685.53 | I10: Contado | J10: 1 año | K10: Ryzen 7 7730U, 16 GB RAM, SSD 512 GB, pantalla 15.6″ Full HD, gráficos Radeon, Windows 11 Home, lector de huella y certificación MIL-STD 810H
A13: (a) Se deben presentar tres (3) presupuestos cuando: El valor del gasto supere el monto de pesos un mil ($ 1.000,00). Se pueden presentar al menos tres (3) solicitudes de cotización (del bien o servicio a contratar) cursadas a tres o más empresas oferentes. La selección del proveedor se hará con el criterio del más bajo precio. En caso de no contar con tres (3) presupuestos, o no poder seleccionar al proveedor que ofrece menor precio, presentar este cuadro una nota de justificación siguiendo las pautas del ítem (XX)
A15: (b) Ejemplos: En el caso de viajes, indicar Origen/Destino (si corresponde también escalas) Si se tratara de servicios tipo catering, indicar las cantidades de asistentes, así como los días en que se demanda la prestación del servicio. Si fuera papelería indicar, cantidades de afiches, trípticos, etc.

Sheet Almacenamiento nosotros
A1: M
D2: CUADRO DE COTIZACIONES
A5: Cuadro Comparativo de Cotizaciones
A7: Presupuestos (a) | B7: Empresa (Nombre fiscal de la empresa) | C7: Nº de CUIT, Dirección, Teléfono (Datos de la empresa) | D7: Descripción del bien/ servicio (b) Características de los bienes/ servicios | E7: Importe Unitario (moneda nacional) | F7: Importe Total IVA incluido (moneda nacional) | G7: Importe Total (moneda extranjera) | H7: Tipo de cambio | I7: Forma de Pago (Contado o Cheque) | J7: Garantía | K7: Observaciones (se debe incluir toda aquella característica que no ha sido posible incluir anteriormente)
A8: Nº 1 | B8: Unilago | C8: https://unilago.com/producto/53338-Disco-Est?srsltid=AfmBOoruL-lQfsUbrTJoBmfuCSMPbY4XcXWeFYUkaxdoZs6XwZYXag5VzcM | D8: 512 GB | E8: 325210.08 | F8: 387000 | G8: 104,78 | H8: 3685.53 | I8: Contado | J8: 36 meses | K8: Capacidad: 512 Gb\nVel. de Lectura: 1600MB/s\nVel. de Escritura: 1600MB/s\nFactor de Forma: M2 PCIE NVME\nGarantia: 36 meses
A9: Nº2 | B9: Mercado libre | C9: https://www.mercadolibre.com.co/disco-solido-ssd-interno-kingspec-ne512-512gb-m2-mvme-2280/up/MCOU2477622600 | D9: 512 GB | E9: 284873.95 | F9: 339000 | G9: 91,79 | H9: 3685.53 | I9: Contado | J9: 6 meses | K9: M.2 2280
A10: Nº 3 | B10: Exito | C10: https://www.exito.com/disco-duro-estado-solido-ssd-hiksemi-m2-pcie-nvme-512gb-104226281-mp/p?idsku=104226281&srsltid=AfmBOorUzAd3JS7H-EdGjUP3yMwNexywbYTmrkV28JZHi6ZmprT0P7ElqJc | D10: 512 GB | E10: 294033.61 | F10: 349900 | G10: 94,74 | H10: 3685.53 | I10: Contado | J10: 1 año | K10: Hiksemi M2 Pcie Nvme 512Gb
A13: (a) Se deben presentar tres (3) presupuestos cuando: El valor del gasto supere el monto de pesos un mil ($ 1.000,00). Se pueden presentar al menos tres (3) solicitudes de cotización (del bien o servicio a contratar) cursadas a tres o más empresas oferentes. La selección del proveedor se hará con el criterio del más bajo precio. En caso de no contar con tres (3) presupuestos, o no poder seleccionar al proveedor que ofrece menor precio, presentar este cuadro una nota de justificación siguiendo las pautas del ítem (XX)
A15: (b) Ejemplos: En el caso de viajes, indicar Origen/Destino (si corresponde también escalas) Si se tratara de servicios tipo catering, indicar las cantidades de asistentes, así como los días en que se demanda la prestación del servicio. Si fuera papelería indicar, cantidades de afiches, trípticos, etc.

Sheet RAM nosotros
D2: CUADRO DE COTIZACIONES
A5: Cuadro Comparativo de Cotizaciones
A7: Presupuestos (a) | B7: Empresa (Nombre fiscal de la empresa) | C7: Nº de CUIT, Dirección, Teléfono (Datos de la empresa) | D7: Descripción del bien/ servicio (b) Características de los bienes/ servicios | E7: Importe Unitario (moneda nacional) | F7: Importe Total IVA incluido (moneda nacional) | G7: Importe Total (moneda extranjera) | H7: Tipo de cambio | I7: Forma de Pago (Contado o Cheque) | J7: Garantía | K7: Observaciones (se debe incluir toda aquella característica que no ha sido posible incluir anteriormente)
A8: Nº 1 | B8: Mercado libre | C8: https://www.mercadolibre.com.co/memoria-adata-ram-portatil-ddr5-16gb-bus-4800/up/MCOU2483034876 | D8: 16 GB RAM DDR5 | E8: 1014201.7 | F8: 1206900 | G8: 326,78 | H8: 3685.53 | I8: Contado | J8: 6 meses | K8: Memoria DDR5 SODIMM que mejora el rendimiento del equipo, con velocidad de hasta 4.8 GHz y una tasa de transferencia de 21.3 GB/s, ideal para optimizar el desempeño del computador.
A9: Nº2 | B9: Falabella | C9: https://www.falabella.com.co/falabella-co/product/132167823/Memoria-Ram-Adata-Para-Portatil-O-Aio-16gb-Ddr5-4800-MHz/132167824 | D9: 16 GB RAM DDR5 | E9: 630168.07 | F9: 749900 | G9: 203,04 | H9: 3685.53 | I9: Contado | J9: 1 año | K9: Memoria Ram Adata Para Portatil O Aio 16gb Ddr5 4800 MHz
A10: Nº 3 | B10: Exito | C10: https://www.exito.com/memoria-ram-portatil-16gb-ddr5-adata-4800-mts-102561351-mp/p?idsku=102561351&srsltid=AfmBOorr8ZTnvWbBCaj0tAL00_P6AQF-hL5xw-v_nvKFt9ZzNkHoYYIcH_w | D10: 16 GB RAM DDR5 | E10: 755462.18 | F10: 899000 | G10: 243,41 | H10: 3685.53 | I10: Contado | J10: 1 año | K10: Memoria DDR5-4800 SO-DIMM con mayor velocidad, mejor estabilidad gracias a la corrección de errores y mayor eficiencia energética al funcionar a 1,1 V.
A13: (a) Se deben presentar tres (3) presupuestos cuando: El valor del gasto supere el monto de pesos un mil ($ 1.000,00). Se pueden presentar al menos tres (3) solicitudes de cotización (del bien o servicio a contratar) cursadas a tres o más empresas oferentes. La selección del proveedor se hará con el criterio del más bajo precio. En caso de no contar con tres (3) presupuestos, o no poder seleccionar al proveedor que ofrece menor precio, presentar este cuadro una nota de justificación siguiendo las pautas del ítem (XX)
A15: (b) Ejemplos: En el caso de viajes, indicar Origen/Destino (si corresponde también escalas) Si se tratara de servicios tipo catering, indicar las cantidades de asistentes, así como los días en que se demanda la prestación del servicio. Si fuera papelería indicar, cantidades de afiches, trípticos, etc.

Sheet Mouse nosotros
D2: CUADRO DE COTIZACIONES
A5: Cuadro Comparativo de Cotizaciones
A7: Presupuestos (a) | B7: Empresa (Nombre fiscal de la empresa) | C7: Nº de CUIT, Dirección, Teléfono (Datos de la empresa) | D7: Descripción del bien/ servicio (b) Características de los bienes/ servicios | E7: Importe Unitario (moneda nacional) | F7: Importe Total IVA incluido (moneda nacional) | G7: Importe Total (moneda extranjera) | H7: Tipo de cambio | I7: Forma de Pago (Contado o Cheque) | J7: Observaciones (se debe incluir toda aquella característica que no ha sido posible incluir anteriormente)
A8: Nº 1 | B8: Mercado libre | C8: https://www.mercadolibre.com.co/mouse-logitech-mx-master-3s-inalambrico-10m-color-grafito/p/MCO2057634967?matt_tool=19390127&utm_source=google_shopping&utm_medium=organic&pdp_filters=item_id%3AMCO2928069778&from=gshop | D8: Mouse Logitech Mx Master 3s | E8: 420089.08 | F8: 499906 | G8: 135,35 | H8: 3685.53 | I8: Contado | J8: Inalámbrico 10m Color Grafito
A9: Nº2 | B9: Exito | C9: https://www.exito.com/mouse-inalambrico-recargable-logitech-mx-master-3s-grafito-102214351-mp/p?idsku=102214351&srsltid=AfmBOoq9Xsr4XUFw85B8u3pz40gh-367Q5VOdKIrJ3tVwbhf2Dt2dGAXg80 | D9: Mouse Logitech Mx Master 3s | E9: 500000 | F9: 595000 | G9: 161,10 | H9: 3685.53 | I9: Contado | J9: El MX Master 3S es un mouse inalámbrico con sensor Darkfield de hasta 8000 dpi, 7 botones, rueda SmartShift y batería recargable con carga rápida.
A10: Nº 3 | B10: Alkosto | C10: https://www.alkosto.com/mouse-logitech-inalambrico-bluetooth-optico-mx-master-3s/p/097855175359?utm_source=google&utm_medium=organic&utm_campaign=Shopping-Organico&srsltid=AfmBOoopbFAEMc5d7ACI0-PuAfwymwQtAgO2df3p-7Oh4Nhn1rx-hMReoz8 | D10: Mouse Logitech Mx Master 3s | E10: 520924.37 | F10: 619900 | G10: 167,84 | H10: 3685.53 | I10: Contado | J10: El MX Master 3S es un mouse con sensor de 8000 dpi, clics silenciosos, hasta 70 días de batería y conexión a tres dispositivos por Bluetooth o Logi Bolt.
A13: (a) Se deben presentar tres (3) presupuestos cuando: El valor del gasto supere el monto de pesos un mil ($ 1.000,00). Se pueden presentar al menos tres (3) solicitudes de cotización (del bien o servicio a contratar) cursadas a tres o más empresas oferentes. La selección del proveedor se hará con el criterio del más bajo precio. En caso de no contar con tres (3) presupuestos, o no poder seleccionar al proveedor que ofrece menor precio, presentar este cuadro una nota de justificación siguiendo las pautas del ítem (XX)
A15: (b) Ejemplos: En el caso de viajes, indicar Origen/Destino (si corresponde también escalas) Si se tratara de servicios tipo catering, indicar las cantidades de asistentes, así como los días en que se demanda la prestación del servicio. Si fuera papelería indicar, cantidades de afiches, trípticos, etc.

Sheet Disco duro externo nosotros
D2: CUADRO DE COTIZACIONES
A5: Cuadro Comparativo de Cotizaciones
A7: Presupuestos (a) | B7: Empresa (Nombre fiscal de la empresa) | C7: Nº de CUIT, Dirección, Teléfono (Datos de la empresa) | D7: Descripción del bien/ servicio (b) Características de los bienes/ servicios | E7: Importe Unitario (moneda nacional) | F7: Importe Total IVA incluido (moneda nacional) | G7: Importe Total (moneda extranjera) | H7: Tipo de cambio | I7: Forma de Pago (Contado o Cheque) | J7: Garantía | K7: Observaciones (se debe incluir toda aquella característica que no ha sido posible incluir anteriormente)
A8: Nº 1 | B8: Mercado libre | C8: https://articulo.mercadolibre.com.co/MCO-2236719560-disco-duro-externo-de-1-tb-de-estilo-nuevo-_JM?matt_tool=19390127&utm_source=google_shopping&utm_medium=organic | D8: Disco duro Extendo 1 TB | E8: 41332.77 | F8: 49186 | G8: 13,32 | H8: 3685.53 | I8: Contado | J8: 60 días | K8: SSD portátil USB 3.1 con alta velocidad de transferencia, gran capacidad, conector OTG, diseño delgado y resistente de aluminio, y amplia compatibilidad con varios dispositivos.
A9: Nº2 | B9: Ktronix | C9: https://www.ktronix.com/disco-estado-solido-externo-ssd-kingston-xs1000-1tb-rojo/p/740617343748?utm_source=google&utm_medium=organic&utm_campaign=Shopping-organico&srsltid=AfmBOopSoaXg4kZta4TC0pM8kGWRhkvq21vh-XjaQANXGX_sZ_mSEwwnn0g | D9: Disco duro Extendo 1 TB | E9: 419327.73 | F9: 499000 | G9: 135,11 | H9: 3685.53 | I9: Contado | J9: 6 meses | K9: La SSD XS1000 de Kingston es compacta, ligera y rápida, ideal para guardar y transferir archivos fácilmente en cualquier lugar.
A10: Nº 3 | B10: Alkosto | C10: https://www.alkosto.com/disco-duro-toshiba-ready-1-tb/p/723844000851?utm_source=google&utm_medium=organic&utm_campaign=Shopping-Organico&srsltid=AfmBOoq20RRhpBms0yg02Lc1nei79ck9okHFJF9yeDTM7CqF4wGeGbYceyo | D10: Disco duro Extendo 1 TB | E10: 294033.61 | F10: 349000 | G10: 94,74 | H10: 3685.53 | I10: Contado | J10: 6 meses | K10: El disco duro portátil Canvio Ready de Toshiba ofrece 1TB de almacenamiento, funcionamiento plug and play y un diseño compacto y elegante, permitiendo guardar archivos fácilmente con solo arrastrar y soltar.
A13: (a) Se deben presentar tres (3) presupuestos cuando: El valor del gasto supere el monto de pesos un mil ($ 1.000,00). Se pueden presentar al menos tres (3) solicitudes de cotización (del bien o servicio a contratar) cursadas a tres o más empresas oferentes. La selección del proveedor se hará con el criterio del más bajo precio. En caso de no contar con tres (3) presupuestos, o no poder seleccionar al proveedor que ofrece menor precio, presentar este cuadro una nota de justificación siguiendo las pautas del ítem (XX)
A15: (b) Ejemplos: En el caso de viajes, indicar Origen/Destino (si corresponde también escalas) Si se tratara de servicios tipo catering, indicar las cantidades de asistentes, así como los días en que se demanda la prestación del servicio. Si fuera papelería indicar, cantidades de afiches, trípticos, etc.

Sheet windows 11 licencia
D2: CUADRO DE COTIZACIONES
A5: Cuadro Comparativo de Cotizaciones
A7: Presupuestos (a) | B7: Empresa (Nombre fiscal de la empresa) | C7: Nº de CUIT, Dirección, Teléfono (Datos de la empresa) | D7: Descripción del bien/ servicio (b) Características de los bienes/ servicios | E7: Importe Unitario (moneda nacional) | F7: Importe Total IVA incluido (moneda nacional) | G7: Importe Total (moneda extranjera) | H7: Tipo de cambio | I7: Forma de Pago (Contado o Cheque) | J7: Observaciones (se debe incluir toda aquella característica que no ha sido posible incluir anteriormente)
A8: Nº 1 | B8: Eneba | C8: https://www.eneba.com/es/microsoft-windows-microsoft-windows-11-professional-key-global/frosty-entertainment?product=digital&currency=COP&utm_adid=&utm_campaign=&utm_content=&utm_source=google-ads&utm_term=&gad_source=4&gad_campaignid=19499769054&gclid=Cj0KCQjwsdnNBhC4ARIsAA_3hehjcBU4WTYWr1WNUvm-Xi6Q28fzcJ5STRRdAFmQ4Rztb-NgqE8ChboaAkvfEALw_wcB | D8: Microsoft Windows 11 Pro | E8: 31502.13 | F8: 37487.53 | G8: 10,14 | H8: 3685.53 | I8: Contado | J8: Proporciona una clave que permite la activacion de Windows 11 Pro
A9: Nº2 | B9: Mercado libre | C9: https://articulo.mercadolibre.com.co/MCO-1847545845-licencia-windows-1011-pro-clave-de-activacion-original-_JM?matt_tool=42084218&matt_word=&matt_source=google&matt_campaign_id=23547382064&matt_ad_group_id=198736076811&matt_match_type=&matt_network=g&matt_device=c&matt_creative=796800778046&matt_keyword=&matt_ad_position=&matt_ad_type=pla&matt_merchant_id=5739952429&matt_product_id=MCO1847545845&matt_product_partition_id=2453251494616&matt_target_id=pla-2453251494616&cq_src=google_ads&cq_cmp=23547382064&cq_net=g&cq_plt=gp&cq_med=pla&gad_source=4&gad_campaignid=23547382064&gclid=Cj0KCQjwsdnNBhC4ARIsAA_3hejpAFAgMl4XBcZ6WfOBZNZvubx28-LxlpLM-WKHnDQgsux4GHLFQx0aAi5VEALw_wcB | D9: Licencia Windows 10/11 Pro | E9: 32773.11 | F9: 39.9 | G9: 10,56 | H9: 3685.53 | I9: Contado | J9: Clave De Activacion Original, duracion permanente
A10: Nº 3 | B10: Revolution software Colombia | C10: https://revolutionsoft.com.co/windows-11/windows-11-pro.html?id_product_attribute=0&gad_source=1&gad_campaignid=23455508345&gclid=Cj0KCQjwsdnNBhC4ARIsAA_3heh6bxXgaXqyBGVlcKNdyYTDoRoNcOMNnE_-QZjKSYuc1RfEXdSFUBwaAjOQEALw_wcB | D10: Licencia Windows 11 PRO | E10: 58235.29 | F10: 69300 | G10: 18,76 | H10: 3685.53 | I10: Contado | J10: Licencia de Windows 11 Pro para 1 PC. Activación permanente con Product Key original de Microsoft. Incluye BitLocker, Escritorio Remoto, Hyper-V, cifrado de dispositivo y todas las funciones profesionales. Sin suscripción.
A13: (a) Se deben presentar tres (3) presupuestos cuando: El valor del gasto supere el monto de pesos un mil ($ 1.000,00). Se pueden presentar al menos tres (3) solicitudes de cotización (del bien o servicio a contratar) cursadas a tres o más empresas oferentes. La selección del proveedor se hará con el criterio del más bajo precio. En caso de no contar con tres (3) presupuestos, o no poder seleccionar al proveedor que ofrece menor precio, presentar este cuadro una nota de justificación siguiendo las pautas del ítem (XX)
A15: (b) Ejemplos: En el caso de viajes, indicar Origen/Destino (si corresponde también escalas) Si se tratara de servicios tipo catering, indicar las cantidades de asistentes, así como los días en que se demanda la prestación del servicio. Si fuera papelería indicar, cantidades de afiches, trípticos, etc.

Sheet Servicio Nube
D2: CUADRO DE COTIZACIONES
A5: Cuadro Comparativo de Cotizaciones
A7: Servicio Paas
B8: Empresa (Nombre fiscal de la empresa) | C8: Nº de CUIT, Dirección, Teléfono (Datos de la empresa) | D8: Descripción del bien/ servicio (b) Características de los bienes/ servicios | E8: Importe Unitario (moneda nacional) | F8: Importe Total IVA incluido (moneda nacional) | G8: Importe Total (moneda extranjera) | H8: Tipo de cambio | I8: Forma de Pago (Contado o Cheque) | J8: Observaciones (se debe incluir toda aquella característica que no ha sido posible incluir anteriormente)
A9: Nº 1 | B9: Microsoft Colombia SAS | C9: https://www.heroku.com/pricing/#managed-data-services | D9: Azure App Service - Plan Basic: PaaS para aplicaciones web y APIs. | E9: 18482.7 | F9: 21994.41 | G9: 5 | H9: 3685.53 | I9: Contado | J9: 512 MB RAM, despliegue vía Git/GitHub y métricas básicas.
A10: Nº2 | B10: Microsoft Colombia SAS | C10: https://azure.microsoft.com/es-es/pricing/details/app-service/linux/ | D10: Azure App Service - Plan Basic (B1): PaaS para aplicaciones web y APIs. | E10: 48717.17 | F10: 57973.43 | G10: 13.25 | H10: 3685.53 | I10: Contado | J10: 1.75 GB RAM, 10 GB almacenamiento, dominio personalizado y certificados SSL.
A11: Nº 3 | B11: Google Colombia Service S.A.S. | C11: https://cloud.google.com/appengine/pricing?hl=es | D11: Instancia Tipo B1 (Escalado Básico). | E11: 146000 | F11: 93415 | G11: 23.35 | H11: 3685.53 | I11: Contado | J11: 128 MB RAM, 600 MHz CPU, incluye 9 horas gratis al día por proyecto.
A13: Servicio DBaas
A14: Presupuestos (a) | B14: Empresa (Nombre fiscal de la empresa) | C14: Nº de CUIT, Dirección, Teléfono (Datos de la empresa) | D14: Descripción del bien/ servicio (b) Características de los bienes/ servicios | E14: Importe Unitario (moneda nacional) | F14: Importe Total IVA incluido (moneda nacional) | G14: Importe Total (moneda extranjera) | H14: Tipo de cambio | I14: Forma de Pago (Contado o Cheque) | J14: Observaciones (se debe incluir toda aquella característica que no ha sido posible incluir anteriormente)
A15: Nº 1 | B15: Salesforce.com, Inc. (Heroku) | C15: https://devcenter.heroku.com/articles/heroku-postgres-plans | D15: Plan Esencial-0 | E15: 18427.65 | F15: 21928.9 | G15: 5 | H15: 3685.53 | I15: Contado | J15: 1 GB de almacenamiento, 20 conexiones simultáneas, RAM compartida.
A16: Nº2 | B16: MongoDB Colombia | C16: https://www.mongodb.com/pricing | D16: 2 GB RAM dedicada, 10 GB almacenamiento SSD, copias de seguridad automáticas y red redundante. | E16: 73710.6 | F16: 87715.61 | G16: 20 | H16: 3685.53 | I16: Contado | J16: 1.75 GB RAM, 10 GB almacenamiento, dominio personalizado y certificados SSL.
A17: Nº 3 | B17: Oracle Colombia S.A.S. | C17: https://www.oracle.com/autonomous-database/pricing/?source=:ow:o:p:mt:::ODBHeader_latam | D17: MySQL Database Service con HeatWave | E17: 147421.2 | F17: 175431.22 | G17: 40 | H17: 3685.53 | I17: Contado | J17: 1 ECPU, 150 GB de Almacenamiento SSD y 100 GB de Backup. Incluye soporte empresarial y alta disponibilidad.
A19: Servicio Iaas
A20: Presupuestos (a) | B20: Empresa (Nombre fiscal de la empresa) | C20: Nº de CUIT, Dirección, Teléfono (Datos de la empresa) | D20: Descripción del bien/ servicio (b) Características de los bienes/ servicios | E20: Importe Unitario (moneda nacional) | F20: Importe Total IVA incluido (moneda nacional) | G20: Importe Total (moneda extranjera) | H20: Tipo de cambio | I20: Forma de Pago (Contado o Cheque) | J20: Observaciones (se debe incluir toda aquella característica que no ha sido posible incluir anteriormente)
A21: Nº 1 | B21: Amazon Data Services Colombia S.A.S. | C21: https://aws.amazon.com/es/ec2/pricing/ | D21: Instancia EC2 t3.medium | E21: 153318.04 | F21: 182448.47 | G21: 41.6 | H21: 3685.53 | I21: Contado | J21: 2 vCPU, 4 GiB RAM. Ideal para servidores web empresariales.
A22: Nº2 | B22: DigitalOcean | C22: https://www.digitalocean.com/pricing | D22: Droplet Basic (1GB RAM, 1 CPU) | E22: 22113.45 | F22: 26315 | G22: 6 | H22: 3685.53 | I22: Contado | J22: 1 vCPU, 1 GiB RAM. Configuración básica optimizada para aplicaciones ligeras, entornos de prueba o blogs personales.
A23: Nº 3 | B23: Linode (Akamai) | C23: https://www.akamai.com/cloud/pricing | D23: Dedicated CPU (4GB RAM, 2 CPU) | E23: 132681.51 | F23: 157891 | G23: 36 | H23: 3685.53 | I23: Contado | J23: 2 vCPU, 4 GiB RAM. CPU dedicada para cargas de trabajo intensivas; garantiza un rendimiento constante sin fluctuaciones de recursos shared.
A24: Servicio Saas
A25: Presupuestos (a) | B25: Empresa (Nombre fiscal de la empresa) | C25: Nº de CUIT, Dirección, Teléfono (Datos de la empresa) | D25: Descripción del bien/ servicio (b) Características de los bienes/ servicios | E25: Importe Unitario (moneda nacional) | F25: Importe Total IVA incluido (moneda nacional) | G25: Importe Total (moneda extranjera) | H25: Tipo de cambio | I25: Forma de Pago (Contado o Cheque) | J25: Observaciones (se debe incluir toda aquella característica que no ha sido posible incluir anteriormente)
A26: Nº 1 | B26: Zoho CRM | C26: https://www.zoho.com/es-xl/crm/zohocrm-pricing.html | D26: Standard | E26: 36858.39 | F26: 43861.48 | G26: 12 | H26: 3685.53 | I26: Contado | J26: Incluye flujos de trabajo, automatización de ventas, paneles personalizados y hasta 100,000 registros. Ideal para PyMEs que inician en gestión digital.
A27: Nº2 | B27: Microsoft | C27: https://www.microsoft.com/es-co/microsoft-365/business/microsoft-365-plans-and-pricing | D27: Microsoft 365 Business Standard | E27: 37472.69 | F27: 44592.5 | G27: 12.5 | H27: 3685.53 | I27: Contado | J27: Incluye versiones de escritorio de Office, 1 TB de almacenamiento en la nube, gestión de correos corporativos y herramientas de colaboración (Teams).
A28: Nº 3 | B28: Salesforce | C28: https://www.salesforce.com/eu/small-business/pricing/ | D28: Paquete básico | E28: 76788.3 | F28: 91378.08 | G28: 25 | H28: 3685.53 | I28: Contado | J28: Solución integral de ventas, servicio y marketing en una sola app. Incluye gestión de leads y soporte al cliente para equipos pequeños.
A29: Servicio Caas
A30: Presupuestos (a) | B30: Empresa (Nombre fiscal de la empresa) | C30: Nº de CUIT, Dirección, Teléfono (Datos de la empresa) | D30: Descripción del bien/ servicio (b) Características de los bienes/ servicios | E30: Importe Unitario (moneda nacional) | F30: Importe Total IVA incluido (moneda nacional) | G30: Importe Total (moneda extranjera) | H30: Tipo de cambio | I30: Forma de Pago (Contado o Cheque) | J30: Observaciones (se debe incluir toda aquella característica que no ha sido posible incluir anteriormente)
A31: Nº 1 | B31: DigitalOcean | C31: https://www.digitalocean.com/pricing/app-platform | D31: Nivel gratuito | E31: 0 | F31: 0 | G31: 0 | H31: 3685.53 | I31: Contado | J31: Nivel gratuito para el despliegue de hasta 3 sitios estáticos. Ideal para pruebas de concepto y prototipado rápido sin gestión de servidores.
A32: Nº2 | B32: AWS | C32: https://aws.amazon.com/es/fargate/pricing/ | D32: Amazon ECS (Fargate 2vCPU/4GB) | E32: 176900.84 | F32: 210512 | G32: 48 | H32: 3685.53 | I32: Contado | J32: Amazon ECS con Fargate (vCPU/4GB). Motor de computación sin servidor para contenedores; elimina la necesidad de gestionar instancias EC2. Pago por uso basado en recursos consumidos.
A33: Nº 3 | B33: Red Hat | C33: https://azure.microsoft.com/es-es/pricing/details/openshift/#pricing | D33: OpenShift Dedicated (Managed) | E33: 767883 | F33: 913780.77 | G33: 250 | H33: 3685.53 | I33: Contado | J33: Incluye soporte premium, seguridad empresarial y operaciones integradas por Red Hat.
A34: Servicio Faas
A35: Presupuestos (a) | B35: Empresa (Nombre fiscal de la empresa) | C35: Nº de CUIT, Dirección, Teléfono (Datos de la empresa) | D35: Descripción del bien/ servicio (b) Características de los bienes/ servicios | E35: Importe Unitario (moneda nacional) | F35: Importe Total IVA incluido (moneda nacional) | G35: Importe Total (moneda extranjera) | H35: Tipo de cambio | I35: Forma de Pago (Contado o Cheque) | J35: Observaciones (se debe incluir toda aquella característica que no ha sido posible incluir anteriormente)
A36: Nº 1 | B36: Cloudflare | C36: https://workers.cloudflare.com/es-es/pricing#compute | D36: Cloudflare Workers (Paid tier) | E36: 18426.89 | F36: 21928 | G36: 5 | H36: 3685.53 | I36: Contado | J36: Ejecución de código en el borde (Edge Computing) con latencia mínima. Incluye 10 millones de solicitudes al mes y mayor tiempo de CPU por ejecución.
A37: Nº2 | B37: Google Cloud | C37: https://cloud.google.com/pricing?hl=es | D37: Plan gratuito | E37: 0 | F37: 0 | G37: 0 | H37: 3685.53 | I37: Contado | J37: Permite ejecutar funciones en respuesta a eventos de HTTP o triggers de Firebase. Incluye hasta 2 millones de invocaciones gratis al mes.
A38: Nº 3 | B38: Vercel | C38: https://vercel.com/pricing | D38: Vercel Pro | E38: 61430.64 | F38: 73102.46 | G38: 20 | H38: 3685.53 | I38: Contado | J38: Optimizado para funciones Serverless integradas con frameworks de Frontend. Incluye mayor concurrencia, logs detallados y herramientas de colaboración para equipos.
A39: Servicio Baas
A40: Presupuestos (a) | B40: Empresa (Nombre fiscal de la empresa) | C40: Nº de CUIT, Dirección, Teléfono (Datos de la empresa) | D40: Descripción del bien/ servicio (b) Características de los bienes/ servicios | E40: Importe Unitario (moneda nacional) | F40: Importe Total IVA incluido (moneda nacional) | G40: Importe Total (moneda extranjera) | H40: Tipo de cambio | I40: Forma de Pago (Contado o Cheque) | J40: Observaciones (se debe incluir toda aquella característica que no ha sido posible incluir anteriormente)
A41: Nº 1 | B41: Supabase | C41: https://supabase.com/pricing | D41: Servicio gratuito | E41: 0 | F41: 0 | G41: 0 | H41: 3685.53 | I41: Contado | J41: Alternativa de código abierto a Firebase basada en PostgreSQL. Incluye base de datos en tiempo real, autenticación y almacenamiento de archivos hasta 500MB.
A42: Nº2 | B42: Firebase (Google) | C42: https://firebase.google.com/pricing?hl=es-419 | D42: Blaze Plan (Uso estimado) | E42: 109377.25 | F42: 130158.93 | G42: 35.61 | H42: 3685.53 | I42: Contado | J42: Incluye base de datos NoSQL (Firestore), autenticación escalable, hosting y funciones en la nube integradas.
A43: Nº 3 | B43: Appwrite | C43: https://appwrite.io/pricing | D43: Pro | E43: 76788.3 | F43: 91378,08 | G43: 25 | H43: 3685.53 | I43: Contado | J43: Backend integral para aplicaciones con soporte para bases de datos, usuarios, almacenamiento y funciones. Ofrece límites más altos de ancho de banda y soporte prioritario.
A44: Servicio Aaas
A45: Presupuestos (a) | B45: Empresa (Nombre fiscal de la empresa) | C45: Nº de CUIT, Dirección, Teléfono (Datos de la empresa) | D45: Descripción del bien/ servicio (b) Características de los bienes/ servicios | E45: Importe Unitario (moneda nacional) | F45: Importe Total IVA incluido (moneda nacional) | G45: Importe Total (moneda extranjera) | H45: Tipo de cambio | I45: Forma de Pago (Contado o Cheque) | J45: Observaciones (se debe incluir toda aquella característica que no ha sido posible incluir anteriormente)
A46: Nº 1 | B46: Tableau (Salesforce) | C46: https://www.tableau.com/pricing | D46: Cuadro | E46: 46072.98 | F46: 54826,85 | G46: 15 | H46: 3685.53 | I46: Contado | J46: Permite explorar dashboards y reportes compartidos con alta seguridad y gobernanza de datos.
...

Sheet Ensamblaje
D2: CUADRO DE COTIZACIONES
A5: Cuadro Comparativo de Cotizaciones
A7: RAM
A8: Presupuestos (a) | B8: Empresa (Nombre fiscal de la empresa) | C8: Nº de CUIT, Dirección, Teléfono (Datos de la empresa) | D8: Descripción del bien/ servicio (b) Características de los bienes/ servicios | E8: Importe Unitario (moneda nacional) | F8: Importe Total IVA incluido (moneda nacional) | G8: Importe Total (moneda extranjera) | H8: Tipo de cambio | I8: Forma de Pago (Contado o Cheque) | J8: Garantía | K8: Observaciones (se debe incluir toda aquella característica que no ha sido posible incluir anteriormente)
A9: Nº 1 | B9: Mercado libre | C9: https://www.mercadolibre.com.co/memoria-adata-ram-portatil-ddr5-16gb-bus-4800/up/MCOU2483034876 | D9: 16 GB RAM DDR5 | E9: 1014201.7 | F9: 1206900 | G9: 326,78 | H9: 3685.53 | I9: Contado | J9: 6 meses | K9: Memoria DDR5 SODIMM que mejora el rendimiento del equipo, con velocidad de hasta 4.8 GHz y una tasa de transferencia de 21.3 GB/s, ideal para optimizar el desempeño del computador.
A10: Nº2 | B10: Falabella | C10: https://www.falabella.com.co/falabella-co/product/132167823/Memoria-Ram-Adata-Para-Portatil-O-Aio-16gb-Ddr5-4800-MHz/132167824 | D10: 16 GB RAM DDR5 | E10: 630168.07 | F10: 749900 | G10: 203,04 | H10: 3685.53 | I10: Contado | J10: 1 año | K10: Memoria Ram Adata Para Portatil O Aio 16gb Ddr5 4800 MHz
A11: Nº 3 | B11: Exito | C11: https://www.exito.com/memoria-ram-portatil-16gb-ddr5-adata-4800-mts-102561351-mp/p?idsku=102561351&srsltid=AfmBOorr8ZTnvWbBCaj0tAL00_P6AQF-hL5xw-v_nvKFt9ZzNkHoYYIcH_w | D11: 16 GB RAM DDR5 | E11: 755462.18 | F11: 899000 | G11: 243,41 | H11: 3685.53 | I11: Contado | J11: 1 año | K11: Memoria DDR5-4800 SO-DIMM con mayor velocidad, mejor estabilidad gracias a la corrección de errores y mayor eficiencia energética al funcionar a 1,1 V.
A13: SSD
A14: Presupuestos (a) | B14: Empresa (Nombre fiscal de la empresa) | C14: Nº de CUIT, Dirección, Teléfono (Datos de la empresa) | D14: Descripción del bien/ servicio (b) Características de los bienes/ servicios | E14: Importe Unitario (moneda nacional) | F14: Importe Total IVA incluido (moneda nacional) | G14: Importe Total (moneda extranjera) | H14: Tipo de cambio | I14: Forma de Pago (Contado o Cheque) | J14: Garantía | K14: Observaciones (se debe incluir toda aquella característica que no ha sido posible incluir anteriormente)
A15: Nº 1 | B15: eBay | C15: https://www.ebay.com/itm/186815652287?chn=ps&mkevt=1&mkcid=28&google_free_listing_action=view_item | D15: SSD Kingston NV3 2 2280 NVMe | E15: 510085.3 | F15: 607001.51 | G15: 164.99 | H15: 3685.53 | I15: Contado | J15: 3 años | K15: Está diseñado para ofrecer un rendimiento superiores para necesidades informática, ofrece velocidades de hasta 6000 MB/s. Con capacidad de almacenamiento de 1TB.
A16: Nº2 | B16: Mercado libre | C16: https://www.mercadolibre.com.co/unidad-de-estado-solido-ssd-m2-500gb-kingston-nv2-pcie-40-nvme-snv2s500g/p/MCO19807863 | D16: SSD Kingston NV2 500GB NVMe | E16: 378151 | F16: 450000 | G16: 122 | H16: 3685.53 | I16: Contado | J16: 3 años | K16: Cuenta con un almacenamiento de última generación impulsada por un controlador NVMe para grandes velocidades con menos requisitos de energía y menor temperatura para ayudar a optimizar el rendimiento de tu sistema.
A17: Nº 3 | B17: Tauret | C17: https://tauretcomputadores.com/product/unidad-solida-m-2-kingston-nv3-1tb-6000-4000-mb-s?srsltid=AfmBOooKSuqOd7u7kDn6eP2LCB8eqFAiI1_i9eXS-EBYD--6VKm_bX5Gy4s | D17: Unidad Sólida M.2 Kingston NV3 1TB 6000/4000 MB/s | E17: 546218.49 | F17: 650000 | G17: 178.29 | H17: 3685.53 | I17: Contado | J17: 60 meses | K17: Ofrece velocidades de lectura/escritura de hasta 6000/5000 MB/s, un menor consumo de energía y una reducción del calor, lo que optimiza el rendimiento del sistema sin comprometer el valor.
A18: Pantalla
A19: Presupuestos (a) | B19: Empresa (Nombre fiscal de la empresa) | C19: Nº de CUIT, Dirección, Teléfono (Datos de la empresa) | D19: Descripción del bien/ servicio (b) Características de los bienes/ servicios | E19: Importe Unitario (moneda nacional) | F19: Importe Total IVA incluido (moneda nacional) | G19: Importe Total (moneda extranjera) | H19: Tipo de cambio | I19: Forma de Pago (Contado o Cheque) | J19: Garantía | K19: Observaciones (se debe incluir toda aquella característica que no ha sido posible incluir anteriormente)
A20: Nº 1 | B20: Fallabella | C20: https://www.falabella.com.co/falabella-co/product/145587591/Monitor-Dell-P2425H-238%E2%80%9D-FHD/145587592 | D20: Monitor Dell P2425H 238” FHD | E20: 739411.76 | F20: 879900 | G20: 241,35 | H20: 3685.53 | I20: Contado | J20: 1 año | K20: Su diseño inteligente te permite ajustar la inclinación, altura y giro para encontrar la postura perfecta, minimizando la fatiga durante largas jornadas. Conecta los dispositivos fácilmente a través de sus múltiples puertos, incluyendo HDMI, DisplayPort, VGA, USB 3.2 y USB-C.
A21: Nº2 | B21: techINN | C21: https://www.tradeinn.com/techinn/es/dell-monitor-p2425h-24-full-hd-ips-led/141591717/p?utm_source=google_products&utm_medium=merchant&id_producte=145914088&country=co&srsltid=AfmBOoq59ihBPTQ3wr_9A_p4oI9BkXEdaIowdzpXNJrru8jmtXzCMWovH7Q | D21: Dell Monitor P2425H 24´´ Full HD IPS LED | E21: 474105.04 | F21: 564185 | G21: 154,75 | H21: 3685.53 | I21: Contado | J21: 6 meses | K21: Su pantalla de 60,5 cm FHD (Full HD) y su tasa de refresco (100 Hz) garantizan contenido fluido en alta definición, además, su función de organización inteligente maximiza la productividad y el flujo de trabajo.
A22: Nº 3 | B22: Ubuy | C22: https://www.ubuy.com.co/sp/product/JTHJBDDGC-dell-24-monitor-p2425h?srsltid=AfmBOopqkau0MyL3b1xUS6vadRNiAiL_Uxcai4VxeVCon1Pqb2_eyUoM_hA | D22: Dell P2425H 24" Full HD LED Monitor P2425H | E22: 767452.1 | F22: 913268 | G22: 250,50 | H22: 3685.53 | I22: Contado | J22: 6 meses | K22: Cuenta con una pantalla Full HD de 24 pulgadas con una resolución de 1920 x 1080, que ofrece imágenes nítidas y vibrantes.
A23: SO
A24: Presupuestos (a) | B24: Empresa (Nombre fiscal de la empresa) | C24: Nº de CUIT, Dirección, Teléfono (Datos de la empresa) | D24: Descripción del bien/ servicio (b) Características de los bienes/ servicios | E24: Importe Unitario (moneda nacional) | F24: Importe Total IVA incluido (moneda nacional) | G24: Importe Total (moneda extranjera) | H24: Tipo de cambio | I24: Forma de Pago (Contado o Cheque) | J24: Garantía | K24: Observaciones (se debe incluir toda aquella característica que no ha sido posible incluir anteriormente)
A25: Nº 1 | B25: Linux Ubuntu | C25: https://ubuntu.com/download/desktop | D25: Ubuntu 24.04 LTS | E25: 0 | F25: 0 | G25: 0 | H25: 3685.53 | I25: Contado | K25: Puedes personalizar hasta el último rincón del sistema. No hay procesos ocultos consumiendo la RAM sin permiso.
A26: Nº2 | B26: Windows 11 | C26: https://tulicencias.com/product/windows-11-pro/?currency=COP&utm_id=22950947926&utm_source=google&utm_medium=cpc&utm_device=c&lmx_id=CjwKCAjw-dfOBhAjEiwAq0RwI0WgJOl0Rlvw71dLiyZ-xRqfWjb9HuUaeuQeopdPt2REk4CMary0ixoCetcQAvD_BwE&gad_source=4&gad_campaignid=22950947926&gbraid=0AAAAA9_hf_CTKFfHusDLVYsOW3lLFbsAE&gclid=CjwKCAjw-dfOBhAjEiwAq0RwI0WgJOl0Rlvw71dLiyZ-xRqfWjb9HuUaeuQeopdPt2REk4CMary0ixoCetcQAvD_BwE | D26: Windows 11 Pro OEM | E26: 33529.41 | F26: 39900 | G26: 10.93 | H26: 3685.53 | I26: Contado | K26: Permite correr un Linux completo dentro de Windows, se consigue lo mejor de los dos mundos: las herramientas de Linux y las apps de Windows (Office, Adobe, juegos).
A27: Nº 3 | B27: MacOS | C27: https://dortania.github.io/OpenCore-Install-Guide/ | D27: OpenCore Install Guide | E27: 0 | F27: 0 | G27: 0 | H27: 3685.53 | I27: Contado | K27: Es el único sistema donde puedes programar, compilar y publicar aplicaciones de forma legal para iPhone, iPad y Mac (usando Xcode).

Sheet ParaFiscales
B2: Nomina | E2: Salarios
B3: Salario Minimo | C3: 1750905 | E3: Técnico (etapa práctica) | F3: $1.558.905
B4: Auxilio de Transporte | C4: 249095 | E4: Tecnólogo(etapa práctica) | F4: $1.750.000
B5: Salario Minimo Integral | C5: 22761765 | E5: Profesional | F5: 3000000
B6: Total | C6: =SUM(C3:C5) -> 24761765 | E6: Valor hora ordinaria (sin pres.) | F6: 7295
B7: Aportes Fiscales | E7: Valor hora ordinaria | F7: 10213
B8: SENA | C8: 0.02 | E8: Recargos Legales
B9: ICBF | C9: 0.03 | E9: Hora extra diurna(sin pres.) | F9: 9119
B10: Cajas | C10: 0.04 | E10: Hora nocturna(sin pres.) | F10: 9848
B11: Total | C11: =SUM(C8:C10) -> 0.09 | E11: Hora extra nocturna(sin pres.) | F11: 12766
B12: Cargas Prestacionales | E12: Dominical / festivo(sin pres) | F12: 12766
B13: Cesantias | C13: 0.0833 | E13: Hora extra diurna | F13: 12766
B14: Intereses a las Cesantias | C14: 0.01 | E14: Hora nocturna | F14: 13787
B15: Prima de Servicios | C15: 0.0833 | E15: Hora extra nocturna | F15: 17872
B16: Vacaciones | C16: 0.0417 | E16: Dominical / festivo | F16: 17872
B17: Total | C17: =SUM(C13:C16) -> 0.2183 | E17: Alquiler
B18: Seguridad Social | E18: Alquiler portátil (mes) | F18: 200000
B19: Salud
B20: Empresa | C20: 0.085 | E20: Gastos Administrativos
B21: Empleado | C21: 0.04 | E21: Concepto | F21: Valor | G21: Mes 1 | H21: Total Año
B22: Pension | E22: Suscripción PaaS (Azure) | F22: 57973 | G22: =F22 -> 57973 | H22: =G22*12 -> 695676
B23: Empresa | C23: 0.12 | E23: Suscripción AWS | F23: 176900.84 | G23: =F23 -> 176900.84 | H23: =G23*12 -> 2122810.1
B24: Empleado | C24: 0.04 | E24: Internet | F24: 179000 | G24: =F24 -> 179000 | H24: =G24*12 -> 2148000
B25: Total Empresa | C25: =SUM(C20+C23) -> 0.205 | E25: Corel Draw | F25: 124167 | G25: =F25 -> 124167 | H25: =G25*12 -> 1490004
B26: Total Empleado | C26: =SUM(C21+C24) -> 0.08 | G26: =F26 -> 0 | H26: =G26*12 -> 0
B27: Totales | C27: =SUM(C11+C17+C25) -> 0.5133 | E27: Total | F27: =SUM(F22:F26) -> 538040.84 | G27: =SUM(G22:G26) -> 538040.84 | H27: =SUM(H22:H26) -> 6456490.1

Sheet Plan de Inversion
B2: Activos Fijos | H2: Plan de Inversion
B3: Descripcion | C3: Unidad Medida | D3: Cantidad | E3: Valor Unitario | F3: Total | H3: Activos Fijos | I3: =F8 -> 12200000
B4: Máquina de coser industrial | C4: Unidad | D4: 3 | E4: 2500000 | F4: =D4*E4 -> 7500000 | H4: Muebles y Enseres | I4: =F22 -> 1262400
B5: Mesa de corte | C5: Unidad | D5: 2 | E5: 700000 | F5: =D5*E5 -> 1400000 | H5: Maquinaria y Equipo | I5: =F36 -> 9827670
B6: Estanterías | C6: Unidad | D6: 5 | E6: 300000 | F6: =D6*E6 -> 1500000 | H6: Total | I6: =SUM(I3:I5) -> 23290070
B7: Impresora | C7: Unidad | D7: 2 | E7: 900000 | F7: =D7*E7 -> 1800000
B8: Total | F8: =SUM(F4:F7) -> 12200000
B11: Muebles y Enseres
B12: Descripcion | C12: Unidad Medida | D12: Cantidad | E12: Valor Unitario | F12: Total
B13: Escritorio para Oficina | C13: Unidad | D13: 3 | E13: 249900 | F13: =D13*E13 -> 749700
B14: Silla Ergonómica de Oficina | C14: Unidad | D14: 3 | E14: 149900 | F14: =D14*E14 -> 449700
B15: Canecas de Basura | C15: Unidad | D15: 3 | E15: 21000 | F15: =D15*E15 -> 63000
F16: =D16*E16 -> 0
F17: =D17*E17 -> 0
F18: =D18*E18 -> 0
F19: =(D19*E19) -> 0
F20: =(D20*E20) -> 0
F21: =(D21*E21) -> 0
B22: Total | F22: =SUM(F13:F21) -> 1262400
B25: Equipo de Computo
B26: Descripcion | C26: Unidad Medida | D26: Cantidad | E26: Valor Unitario | F26: Total
B27: PORTATIL LENOVO - V14 G4 AMN | C27: Unidad | D27: 2 | E27: 1684400 | F27: =D27*E27 -> 3368800
B28: Portátil ASUS VivoBook 15 | C28: Unidad | D28: 2 | E28: 1979900 | F28: =D28*E28 -> 3959800
B29: Computador Portátil LENOVO Ideapad Slim 3 - 15.3" Pulgadas 15HP10 - AMD Ryzen 5 - RAM 24GB - Disco SSD 512GB - Azul | C29: Unidad | D29: 1 | E29: 2499070 | F29: =D29*E29 -> 2499070
F30: =D30*E30 -> 0
F31: =D31*E31 -> 0
F32: =D32*E32 -> 0
F33: =(D33*E33) -> 0
F34: =(D34*E34) -> 0
F35: =(D35*E35) -> 0
B36: Total | F36: =SUM(F27:F35) -> 9827670

Sheet Gastos de Personal
B2: Requerimiento de Personal | E2: Salud | H2: Pension | K2: Subsidio de Transporte | L2: Total a Pagar
B3: Cargo | C3: Sueldo Mensual | D3: Dias Laborados | E3: Empleado | F3: Empresa | G3: Total | H3: Empleado | I3: Empresa | J3: Total | K3: Empleado | L3: Total
B4: Aprendiz | C4: 1750905 | D4: 30 | E4: =C4*ParaFiscales!$C$21 -> 70036.2 | F4: =C4*ParaFiscales!$C$20 -> 148826.93 | G4: =SUM(E4:F4) -> 218863.12 | H4: =C4*ParaFiscales!$C$24 -> 70036.2 | I4: =C4*ParaFiscales!$C$23 -> 210108.6 | J4: =SUM(H4:I4) -> 280144.8 | K4: 249095 | L4: =(C4-E4-H4+K4) -> 1859927.6
B5: Aprendiz | C5: 1750905 | D5: 30 | E5: =C5*ParaFiscales!$C$21 -> 70036.2 | F5: =C5*ParaFiscales!$C$20 -> 148826.93 | G5: =SUM(E5:F5) -> 218863.12 | H5: =C5*ParaFiscales!$C$24 -> 70036.2 | I5: =C5*ParaFiscales!$C$23 -> 210108.6 | J5: =SUM(H5:I5) -> 280144.8 | K5: 249095 | L5: =(C5-E5-H5+K5) -> 1859927.6
B6: Aprendiz | C6: 1750905 | D6: 30 | E6: =C6*ParaFiscales!$C$21 -> 70036.2 | F6: =C6*ParaFiscales!$C$20 -> 148826.93 | G6: =SUM(E6:F6) -> 218863.12 | H6: =C6*ParaFiscales!$C$24 -> 70036.2 | I6: =C6*ParaFiscales!$C$23 -> 210108.6 | J6: =SUM(H6:I6) -> 280144.8 | K6: 249095 | L6: =(C6-E6-H6+K6) -> 1859927.6
B7: Aprendiz | C7: 1750905 | D7: 30 | E7: =C7*ParaFiscales!$C$21 -> 70036.2 | F7: =C7*ParaFiscales!$C$20 -> 148826.93 | G7: =SUM(E7:F7) -> 218863.12 | H7: =C7*ParaFiscales!$C$24 -> 70036.2 | I7: =C7*ParaFiscales!$C$23 -> 210108.6 | J7: =SUM(H7:I7) -> 280144.8 | K7: 249095 | L7: =(C7-E7-H7+K7) -> 1859927.6
B8: Aprendiz | C8: 1750905 | D8: 30 | E8: 70036.2 | F8: 148826.93 | G8: 218863.12 | H8: 70036.2 | I8: 210108.6 | J8: 280144.8 | K8: 249095 | L8: 1859927.6
E9: =C9*ParaFiscales!$C$22 -> 0 | F9: =C9*ParaFiscales!$C$21 -> 0 | G9: =SUM(E9:F9) -> 0 | H9: =C9*ParaFiscales!$C$25 -> 0 | I9: =C9*ParaFiscales!$C$24 -> 0 | J9: =SUM(H9:I9) -> 0 | L9: =(C9-E9-H9+K9) -> 0
E10: =C10*ParaFiscales!$C$22 -> 0 | F10: =C10*ParaFiscales!$C$21 -> 0 | G10: =SUM(E10:F10) -> 0 | H10: =C10*ParaFiscales!$C$25 -> 0 | I10: =C10*ParaFiscales!$C$24 -> 0 | J10: =SUM(H10:I10) -> 0 | L10: =(C10-E10-H10+K10) -> 0
B11: Totales | C11: =SUM(C4:C10) -> 8754525 | E11: =SUM(E4:E10) -> 350181 | F11: =SUM(F4:F10) -> 744134.63 | G11: =SUM(G4:G10) -> 1094315.6 | H11: =SUM(H4:H10) -> 350181 | I11: =SUM(I4:I10) -> 1050543 | J11: =SUM(J4:J10) -> 1400724 | K11: =SUM(K4:K10) -> 1245475 | L11: =SUM(L4:L10) -> 9299638
C14: DURACION PROYECTO | F14: 8 MESES MAXIMO
C15: GASTOS EN PERSONAL | D15: VALOR | E15: CANTIDAD | F15: SALUD | G15: PENSION | H15: ST | I15: TOTAL
C16: 5 | D16: =SUM(C4:C8) -> 8754525 | E16: 8 | F16: =SUM(E4:E8) -> 350181 | G16: =SUM(H4:H8) -> 350181 | H16: =SUM(K4:K8) -> 1245475 | I16: =D16+G16+F16+H16*E16 -> 19418687

Sheet Costo del Proyecto
B5: Costo Inicial del Proyecto
B6: Concepto | C6: Valor
B7: Plan de Inversión | C7: 23290070
B8: Gastos de Personal | C8: 19418687
B9: Parafiscales | C9: ='[1]Gastos de Personal'!C36 -> 3593100
B10: Gastos Administrativos | C10: ='[1]Gastos Administrativos'!D16 -> 1340000
B11: Total | C11: =SUM(C7:C10) -> 47641857

Sheet Consolidado
B2: Cotización
B3: #VALUE! | C3: Nombre del proyecto: Dotaciones Fortuna IJ
C4: Nombres: Brayan Corpa, Dilan Rodriguez, Antony Cardenas, Samuel Peña, Felipe Lasprilla
C5: Tel: 3150410649
C6: Correo: Juanfelasprilla60@gmail.com
B7: Admistrador: | C7: Harold linares | F7: Número de cotización: | G7: V.3
B8: Número de teléfono del cliente: | C8: 3044740671
B9: Persona de contacto: | C9: Camila Sanchez | F9: Fecha de cotización: | G9: 46118
B10: Dirección del cliente: | C10: cra 68 # 35 a sur 26
B11: 1. Equipos de computo para el administrador
B12: 2. Equipos de computo para el equipo de desarrollo del sistema (CheerClick Systems)
B13: Tipo | C13: Nombre del árticulo | D13: Proveedor | E13: Cantidad | F13: Precio unitario | G13: IVA | H13: Precio final | I13: Argumentación
B14: Portatil Administrador | C14: Portátil Lenovo V14 G4 Ryzen 5 7520U 16Gb Ram 512Gb Ssd 14 Pulgadas Fhd | D14: Exito | E14: 1 | F14: 1415462.2 | G14: 268937.82 | H14: =SUM(F14:G14) -> 1684400 | I14: Se asegurar la productividad del administrador. Un equipo con estas especificaciones aumenta el redimiento de las operaciones a realizar.
